{
 "cells": [
  {
   "metadata": {
    "ExecuteTime": {
     "end_time": "2024-11-16T15:49:30.314764Z",
     "start_time": "2024-11-16T15:49:30.255612Z"
    }
   },
   "cell_type": "code",
   "source": [
    "from pydantic import (\n",
    "    BaseModel,\n",
    "    ConfigDict,\n",
    "    PastDatetime,\n",
    "    PastDate,\n",
    "    AwareDatetime,\n",
    "    NaiveDatetime,\n",
    "    ValidationError\n",
    ")"
   ],
   "id": "aceba7f5738856cb",
   "outputs": [],
   "execution_count": 1
  },
  {
   "metadata": {
    "ExecuteTime": {
     "end_time": "2024-11-16T15:50:28.399587Z",
     "start_time": "2024-11-16T15:50:28.344318Z"
    }
   },
   "cell_type": "code",
   "source": [
    "class Model(BaseModel):\n",
    "    dt: PastDatetime"
   ],
   "id": "4de2c031565652e5",
   "outputs": [],
   "execution_count": 2
  },
  {
   "metadata": {
    "ExecuteTime": {
     "end_time": "2024-11-16T15:53:36.671007Z",
     "start_time": "2024-11-16T15:53:36.667475Z"
    }
   },
   "cell_type": "code",
   "source": [
    "from datetime import datetime, timedelta\n",
    "import pytz"
   ],
   "id": "c785be0e50fb0cee",
   "outputs": [],
   "execution_count": 12
  },
  {
   "metadata": {
    "ExecuteTime": {
     "end_time": "2024-11-16T15:51:22.855294Z",
     "start_time": "2024-11-16T15:51:22.850410Z"
    }
   },
   "cell_type": "code",
   "source": "datetime.now()",
   "id": "4ca525ef75622d3",
   "outputs": [
    {
     "data": {
      "text/plain": [
       "datetime.datetime(2024, 11, 16, 19, 51, 22, 851070)"
      ]
     },
     "execution_count": 4,
     "metadata": {},
     "output_type": "execute_result"
    }
   ],
   "execution_count": 4
  },
  {
   "metadata": {
    "ExecuteTime": {
     "end_time": "2024-11-16T15:52:18.413189Z",
     "start_time": "2024-11-16T15:52:18.260432Z"
    }
   },
   "cell_type": "code",
   "source": "Model(dt=datetime(2024, 11, 16, 19, 53))",
   "id": "fd0193cd43a87ac6",
   "outputs": [
    {
     "ename": "ValidationError",
     "evalue": "1 validation error for Model\ndt\n  Input should be in the past [type=datetime_past, input_value=datetime.datetime(2024, 11, 16, 19, 53), input_type=datetime]\n    For further information visit https://errors.pydantic.dev/2.9/v/datetime_past",
     "output_type": "error",
     "traceback": [
      "\u001B[0;31m---------------------------------------------------------------------------\u001B[0m",
      "\u001B[0;31mValidationError\u001B[0m                           Traceback (most recent call last)",
      "Cell \u001B[0;32mIn[8], line 1\u001B[0m\n\u001B[0;32m----> 1\u001B[0m \u001B[43mModel\u001B[49m\u001B[43m(\u001B[49m\u001B[43mdt\u001B[49m\u001B[38;5;241;43m=\u001B[39;49m\u001B[43mdatetime\u001B[49m\u001B[43m(\u001B[49m\u001B[38;5;241;43m2024\u001B[39;49m\u001B[43m,\u001B[49m\u001B[43m \u001B[49m\u001B[38;5;241;43m11\u001B[39;49m\u001B[43m,\u001B[49m\u001B[43m \u001B[49m\u001B[38;5;241;43m16\u001B[39;49m\u001B[43m,\u001B[49m\u001B[43m \u001B[49m\u001B[38;5;241;43m19\u001B[39;49m\u001B[43m,\u001B[49m\u001B[43m \u001B[49m\u001B[38;5;241;43m53\u001B[39;49m\u001B[43m)\u001B[49m\u001B[43m)\u001B[49m\n",
      "File \u001B[0;32m~/Dev/pydantic-essentials/venv/lib/python3.12/site-packages/pydantic/main.py:212\u001B[0m, in \u001B[0;36mBaseModel.__init__\u001B[0;34m(self, **data)\u001B[0m\n\u001B[1;32m    210\u001B[0m \u001B[38;5;66;03m# `__tracebackhide__` tells pytest and some other tools to omit this function from tracebacks\u001B[39;00m\n\u001B[1;32m    211\u001B[0m __tracebackhide__ \u001B[38;5;241m=\u001B[39m \u001B[38;5;28;01mTrue\u001B[39;00m\n\u001B[0;32m--> 212\u001B[0m validated_self \u001B[38;5;241m=\u001B[39m \u001B[38;5;28;43mself\u001B[39;49m\u001B[38;5;241;43m.\u001B[39;49m\u001B[43m__pydantic_validator__\u001B[49m\u001B[38;5;241;43m.\u001B[39;49m\u001B[43mvalidate_python\u001B[49m\u001B[43m(\u001B[49m\u001B[43mdata\u001B[49m\u001B[43m,\u001B[49m\u001B[43m \u001B[49m\u001B[43mself_instance\u001B[49m\u001B[38;5;241;43m=\u001B[39;49m\u001B[38;5;28;43mself\u001B[39;49m\u001B[43m)\u001B[49m\n\u001B[1;32m    213\u001B[0m \u001B[38;5;28;01mif\u001B[39;00m \u001B[38;5;28mself\u001B[39m \u001B[38;5;129;01mis\u001B[39;00m \u001B[38;5;129;01mnot\u001B[39;00m validated_self:\n\u001B[1;32m    214\u001B[0m     warnings\u001B[38;5;241m.\u001B[39mwarn(\n\u001B[1;32m    215\u001B[0m         \u001B[38;5;124m'\u001B[39m\u001B[38;5;124mA custom validator is returning a value other than `self`.\u001B[39m\u001B[38;5;130;01m\\n\u001B[39;00m\u001B[38;5;124m'\u001B[39m\n\u001B[1;32m    216\u001B[0m         \u001B[38;5;124m\"\u001B[39m\u001B[38;5;124mReturning anything other than `self` from a top level model validator isn\u001B[39m\u001B[38;5;124m'\u001B[39m\u001B[38;5;124mt supported when validating via `__init__`.\u001B[39m\u001B[38;5;130;01m\\n\u001B[39;00m\u001B[38;5;124m\"\u001B[39m\n\u001B[1;32m    217\u001B[0m         \u001B[38;5;124m'\u001B[39m\u001B[38;5;124mSee the `model_validator` docs (https://docs.pydantic.dev/latest/concepts/validators/#model-validators) for more details.\u001B[39m\u001B[38;5;124m'\u001B[39m,\n\u001B[1;32m    218\u001B[0m         category\u001B[38;5;241m=\u001B[39m\u001B[38;5;28;01mNone\u001B[39;00m,\n\u001B[1;32m    219\u001B[0m     )\n",
      "\u001B[0;31mValidationError\u001B[0m: 1 validation error for Model\ndt\n  Input should be in the past [type=datetime_past, input_value=datetime.datetime(2024, 11, 16, 19, 53), input_type=datetime]\n    For further information visit https://errors.pydantic.dev/2.9/v/datetime_past"
     ]
    }
   ],
   "execution_count": 8
  },
  {
   "metadata": {
    "ExecuteTime": {
     "end_time": "2024-11-16T15:53:05.021510Z",
     "start_time": "2024-11-16T15:53:05.009455Z"
    }
   },
   "cell_type": "code",
   "source": [
    "class Model(BaseModel):\n",
    "    dt: NaiveDatetime"
   ],
   "id": "5ccbe3655635b092",
   "outputs": [],
   "execution_count": 9
  },
  {
   "metadata": {
    "ExecuteTime": {
     "end_time": "2024-11-16T15:54:25.670672Z",
     "start_time": "2024-11-16T15:54:25.667141Z"
    }
   },
   "cell_type": "code",
   "source": [
    "local_one_hour_ago = datetime.now() - timedelta(hours=1)\n",
    "local_one_hour_ago"
   ],
   "id": "ecaefe9d35093791",
   "outputs": [
    {
     "data": {
      "text/plain": [
       "datetime.datetime(2024, 11, 16, 18, 54, 25, 668286)"
      ]
     },
     "execution_count": 15,
     "metadata": {},
     "output_type": "execute_result"
    }
   ],
   "execution_count": 15
  },
  {
   "metadata": {
    "ExecuteTime": {
     "end_time": "2024-11-16T15:54:27.584931Z",
     "start_time": "2024-11-16T15:54:27.579140Z"
    }
   },
   "cell_type": "code",
   "source": [
    "utc_one_hour_ago = local_one_hour_ago.astimezone(pytz.utc)\n",
    "utc_one_hour_ago"
   ],
   "id": "f73b01f71dfc3cc5",
   "outputs": [
    {
     "data": {
      "text/plain": [
       "datetime.datetime(2024, 11, 16, 14, 54, 25, 668286, tzinfo=<UTC>)"
      ]
     },
     "execution_count": 16,
     "metadata": {},
     "output_type": "execute_result"
    }
   ],
   "execution_count": 16
  },
  {
   "metadata": {
    "ExecuteTime": {
     "end_time": "2024-11-16T15:54:47.793020Z",
     "start_time": "2024-11-16T15:54:47.788931Z"
    }
   },
   "cell_type": "code",
   "source": "Model(dt=local_one_hour_ago)",
   "id": "de173cbcee124fac",
   "outputs": [
    {
     "data": {
      "text/plain": [
       "Model(dt=datetime.datetime(2024, 11, 16, 18, 54, 25, 668286))"
      ]
     },
     "execution_count": 18,
     "metadata": {},
     "output_type": "execute_result"
    }
   ],
   "execution_count": 18
  },
  {
   "metadata": {
    "ExecuteTime": {
     "end_time": "2024-11-16T15:54:57.016652Z",
     "start_time": "2024-11-16T15:54:56.993308Z"
    }
   },
   "cell_type": "code",
   "source": "Model(dt=utc_one_hour_ago)",
   "id": "bd215c19ef1c22ea",
   "outputs": [
    {
     "ename": "ValidationError",
     "evalue": "1 validation error for Model\ndt\n  Input should not have timezone info [type=timezone_naive, input_value=datetime.datetime(2024, 1...5, 668286, tzinfo=<UTC>), input_type=datetime]\n    For further information visit https://errors.pydantic.dev/2.9/v/timezone_naive",
     "output_type": "error",
     "traceback": [
      "\u001B[0;31m---------------------------------------------------------------------------\u001B[0m",
      "\u001B[0;31mValidationError\u001B[0m                           Traceback (most recent call last)",
      "Cell \u001B[0;32mIn[19], line 1\u001B[0m\n\u001B[0;32m----> 1\u001B[0m \u001B[43mModel\u001B[49m\u001B[43m(\u001B[49m\u001B[43mdt\u001B[49m\u001B[38;5;241;43m=\u001B[39;49m\u001B[43mutc_one_hour_ago\u001B[49m\u001B[43m)\u001B[49m\n",
      "File \u001B[0;32m~/Dev/pydantic-essentials/venv/lib/python3.12/site-packages/pydantic/main.py:212\u001B[0m, in \u001B[0;36mBaseModel.__init__\u001B[0;34m(self, **data)\u001B[0m\n\u001B[1;32m    210\u001B[0m \u001B[38;5;66;03m# `__tracebackhide__` tells pytest and some other tools to omit this function from tracebacks\u001B[39;00m\n\u001B[1;32m    211\u001B[0m __tracebackhide__ \u001B[38;5;241m=\u001B[39m \u001B[38;5;28;01mTrue\u001B[39;00m\n\u001B[0;32m--> 212\u001B[0m validated_self \u001B[38;5;241m=\u001B[39m \u001B[38;5;28;43mself\u001B[39;49m\u001B[38;5;241;43m.\u001B[39;49m\u001B[43m__pydantic_validator__\u001B[49m\u001B[38;5;241;43m.\u001B[39;49m\u001B[43mvalidate_python\u001B[49m\u001B[43m(\u001B[49m\u001B[43mdata\u001B[49m\u001B[43m,\u001B[49m\u001B[43m \u001B[49m\u001B[43mself_instance\u001B[49m\u001B[38;5;241;43m=\u001B[39;49m\u001B[38;5;28;43mself\u001B[39;49m\u001B[43m)\u001B[49m\n\u001B[1;32m    213\u001B[0m \u001B[38;5;28;01mif\u001B[39;00m \u001B[38;5;28mself\u001B[39m \u001B[38;5;129;01mis\u001B[39;00m \u001B[38;5;129;01mnot\u001B[39;00m validated_self:\n\u001B[1;32m    214\u001B[0m     warnings\u001B[38;5;241m.\u001B[39mwarn(\n\u001B[1;32m    215\u001B[0m         \u001B[38;5;124m'\u001B[39m\u001B[38;5;124mA custom validator is returning a value other than `self`.\u001B[39m\u001B[38;5;130;01m\\n\u001B[39;00m\u001B[38;5;124m'\u001B[39m\n\u001B[1;32m    216\u001B[0m         \u001B[38;5;124m\"\u001B[39m\u001B[38;5;124mReturning anything other than `self` from a top level model validator isn\u001B[39m\u001B[38;5;124m'\u001B[39m\u001B[38;5;124mt supported when validating via `__init__`.\u001B[39m\u001B[38;5;130;01m\\n\u001B[39;00m\u001B[38;5;124m\"\u001B[39m\n\u001B[1;32m    217\u001B[0m         \u001B[38;5;124m'\u001B[39m\u001B[38;5;124mSee the `model_validator` docs (https://docs.pydantic.dev/latest/concepts/validators/#model-validators) for more details.\u001B[39m\u001B[38;5;124m'\u001B[39m,\n\u001B[1;32m    218\u001B[0m         category\u001B[38;5;241m=\u001B[39m\u001B[38;5;28;01mNone\u001B[39;00m,\n\u001B[1;32m    219\u001B[0m     )\n",
      "\u001B[0;31mValidationError\u001B[0m: 1 validation error for Model\ndt\n  Input should not have timezone info [type=timezone_naive, input_value=datetime.datetime(2024, 1...5, 668286, tzinfo=<UTC>), input_type=datetime]\n    For further information visit https://errors.pydantic.dev/2.9/v/timezone_naive"
     ]
    }
   ],
   "execution_count": 19
  },
  {
   "metadata": {
    "ExecuteTime": {
     "end_time": "2024-11-16T15:55:25.023234Z",
     "start_time": "2024-11-16T15:55:25.013967Z"
    }
   },
   "cell_type": "code",
   "source": [
    "class Model(BaseModel):\n",
    "    dt: AwareDatetime"
   ],
   "id": "c4ec0bc9f7d88f04",
   "outputs": [],
   "execution_count": 20
  },
  {
   "metadata": {
    "ExecuteTime": {
     "end_time": "2024-11-16T15:55:30.263755Z",
     "start_time": "2024-11-16T15:55:30.242629Z"
    }
   },
   "cell_type": "code",
   "source": "Model(dt=local_one_hour_ago)\n",
   "id": "c5c7b5132aab1811",
   "outputs": [
    {
     "ename": "ValidationError",
     "evalue": "1 validation error for Model\ndt\n  Input should have timezone info [type=timezone_aware, input_value=datetime.datetime(2024, 1... 16, 18, 54, 25, 668286), input_type=datetime]\n    For further information visit https://errors.pydantic.dev/2.9/v/timezone_aware",
     "output_type": "error",
     "traceback": [
      "\u001B[0;31m---------------------------------------------------------------------------\u001B[0m",
      "\u001B[0;31mValidationError\u001B[0m                           Traceback (most recent call last)",
      "Cell \u001B[0;32mIn[21], line 1\u001B[0m\n\u001B[0;32m----> 1\u001B[0m \u001B[43mModel\u001B[49m\u001B[43m(\u001B[49m\u001B[43mdt\u001B[49m\u001B[38;5;241;43m=\u001B[39;49m\u001B[43mlocal_one_hour_ago\u001B[49m\u001B[43m)\u001B[49m\n",
      "File \u001B[0;32m~/Dev/pydantic-essentials/venv/lib/python3.12/site-packages/pydantic/main.py:212\u001B[0m, in \u001B[0;36mBaseModel.__init__\u001B[0;34m(self, **data)\u001B[0m\n\u001B[1;32m    210\u001B[0m \u001B[38;5;66;03m# `__tracebackhide__` tells pytest and some other tools to omit this function from tracebacks\u001B[39;00m\n\u001B[1;32m    211\u001B[0m __tracebackhide__ \u001B[38;5;241m=\u001B[39m \u001B[38;5;28;01mTrue\u001B[39;00m\n\u001B[0;32m--> 212\u001B[0m validated_self \u001B[38;5;241m=\u001B[39m \u001B[38;5;28;43mself\u001B[39;49m\u001B[38;5;241;43m.\u001B[39;49m\u001B[43m__pydantic_validator__\u001B[49m\u001B[38;5;241;43m.\u001B[39;49m\u001B[43mvalidate_python\u001B[49m\u001B[43m(\u001B[49m\u001B[43mdata\u001B[49m\u001B[43m,\u001B[49m\u001B[43m \u001B[49m\u001B[43mself_instance\u001B[49m\u001B[38;5;241;43m=\u001B[39;49m\u001B[38;5;28;43mself\u001B[39;49m\u001B[43m)\u001B[49m\n\u001B[1;32m    213\u001B[0m \u001B[38;5;28;01mif\u001B[39;00m \u001B[38;5;28mself\u001B[39m \u001B[38;5;129;01mis\u001B[39;00m \u001B[38;5;129;01mnot\u001B[39;00m validated_self:\n\u001B[1;32m    214\u001B[0m     warnings\u001B[38;5;241m.\u001B[39mwarn(\n\u001B[1;32m    215\u001B[0m         \u001B[38;5;124m'\u001B[39m\u001B[38;5;124mA custom validator is returning a value other than `self`.\u001B[39m\u001B[38;5;130;01m\\n\u001B[39;00m\u001B[38;5;124m'\u001B[39m\n\u001B[1;32m    216\u001B[0m         \u001B[38;5;124m\"\u001B[39m\u001B[38;5;124mReturning anything other than `self` from a top level model validator isn\u001B[39m\u001B[38;5;124m'\u001B[39m\u001B[38;5;124mt supported when validating via `__init__`.\u001B[39m\u001B[38;5;130;01m\\n\u001B[39;00m\u001B[38;5;124m\"\u001B[39m\n\u001B[1;32m    217\u001B[0m         \u001B[38;5;124m'\u001B[39m\u001B[38;5;124mSee the `model_validator` docs (https://docs.pydantic.dev/latest/concepts/validators/#model-validators) for more details.\u001B[39m\u001B[38;5;124m'\u001B[39m,\n\u001B[1;32m    218\u001B[0m         category\u001B[38;5;241m=\u001B[39m\u001B[38;5;28;01mNone\u001B[39;00m,\n\u001B[1;32m    219\u001B[0m     )\n",
      "\u001B[0;31mValidationError\u001B[0m: 1 validation error for Model\ndt\n  Input should have timezone info [type=timezone_aware, input_value=datetime.datetime(2024, 1... 16, 18, 54, 25, 668286), input_type=datetime]\n    For further information visit https://errors.pydantic.dev/2.9/v/timezone_aware"
     ]
    }
   ],
   "execution_count": 21
  },
  {
   "metadata": {
    "ExecuteTime": {
     "end_time": "2024-11-16T15:55:36.674765Z",
     "start_time": "2024-11-16T15:55:36.668809Z"
    }
   },
   "cell_type": "code",
   "source": "Model(dt=utc_one_hour_ago)\n",
   "id": "d6aeea6ddc964e04",
   "outputs": [
    {
     "data": {
      "text/plain": [
       "Model(dt=datetime.datetime(2024, 11, 16, 14, 54, 25, 668286, tzinfo=<UTC>))"
      ]
     },
     "execution_count": 22,
     "metadata": {},
     "output_type": "execute_result"
    }
   ],
   "execution_count": 22
  }
 ],
 "metadata": {
  "kernelspec": {
   "name": "python3",
   "language": "python",
   "display_name": "Python 3 (ipykernel)"
  }
 },
 "nbformat": 5,
 "nbformat_minor": 9
}
